{
 "cells": [
  {
   "cell_type": "code",
   "execution_count": 5,
   "id": "184f1e15-8d0a-47a7-abab-2348f7872b8d",
   "metadata": {},
   "outputs": [
    {
     "ename": "SyntaxError",
     "evalue": "invalid syntax. Perhaps you forgot a comma? (1238787738.py, line 11)",
     "output_type": "error",
     "traceback": [
      "\u001b[0;36m  Cell \u001b[0;32mIn[5], line 11\u001b[0;36m\u001b[0m\n\u001b[0;31m    print(hello sir kaise ho )\u001b[0m\n\u001b[0m          ^\u001b[0m\n\u001b[0;31mSyntaxError\u001b[0m\u001b[0;31m:\u001b[0m invalid syntax. Perhaps you forgot a comma?\n"
     ]
    }
   ],
   "source": [
    "# Q1. What is an Exception in python?Write the difference between Exceptions and syntax errors?\n",
    "#Answer: Exception is an abnormal event , which occurs during the execution of a program that disrupts the normal flow of the program's \n",
    "        # instruction \n",
    "        # Syntax error are mistakes in the code, such as spelling and punctuation errors, incorrect labels and so on, which cause an error \n",
    "        # message to be generated by the compiler and stops the execution of the program \n",
    "        # OR Syntax Errors are those errors detected during the compilation phase by the compiler when your code does not follow the\n",
    "        # syntactical rules of the programming language.\n",
    "        #the main difference between exception and syntax error is that syntax error occurs during the compliation phase of the code while\n",
    "        # exception occurs during the runtime of the program \n",
    "#example\n",
    "print(hello sir kaise ho )  #this is syntax error, i forgot the inverted commas inside the print function "
   ]
  },
  {
   "cell_type": "code",
   "execution_count": 6,
   "id": "dd7c8738-2e73-46e9-af6b-834dd0725eea",
   "metadata": {},
   "outputs": [
    {
     "name": "stdin",
     "output_type": "stream",
     "text": [
      "Enter the age:  -22\n"
     ]
    }
   ],
   "source": [
    "age = int(input(\"Enter the age: \"))"
   ]
  },
  {
   "cell_type": "code",
   "execution_count": 7,
   "id": "49d1ad6e-c0d7-4ee2-b47a-93e3151cc1dd",
   "metadata": {},
   "outputs": [],
   "source": [
    "# this is  an exception because age never be is negative , it cannot show any error but the normal flow is disrupts"
   ]
  },
  {
   "cell_type": "code",
   "execution_count": 16,
   "id": "3547ae7c-5e48-4562-aac2-c083968c36ea",
   "metadata": {},
   "outputs": [
    {
     "ename": "IndexError",
     "evalue": "list index out of range",
     "output_type": "error",
     "traceback": [
      "\u001b[0;31m---------------------------------------------------------------------------\u001b[0m",
      "\u001b[0;31mIndexError\u001b[0m                                Traceback (most recent call last)",
      "Cell \u001b[0;32mIn[16], line 5\u001b[0m\n\u001b[1;32m      1\u001b[0m \u001b[38;5;66;03m# Q2. What happens when an exception is not handled? Explain with n example\u001b[39;00m\n\u001b[1;32m      2\u001b[0m \u001b[38;5;66;03m#Answer: When the exception is not handled in python code than the code throw an error during the run time and stops the normal flow of \u001b[39;00m\n\u001b[1;32m      3\u001b[0m         \u001b[38;5;66;03m# the program \u001b[39;00m\n\u001b[1;32m      4\u001b[0m a \u001b[38;5;241m=\u001b[39m  [\u001b[38;5;241m1\u001b[39m,\u001b[38;5;241m2\u001b[39m,\u001b[38;5;241m3\u001b[39m,\u001b[38;5;241m4\u001b[39m,\u001b[38;5;241m5\u001b[39m]    \u001b[38;5;66;03m#list of 5 elements\u001b[39;00m\n\u001b[0;32m----> 5\u001b[0m \u001b[43ma\u001b[49m\u001b[43m[\u001b[49m\u001b[38;5;241;43m5\u001b[39;49m\u001b[43m]\u001b[49m             \u001b[38;5;66;03m# we want to access the element that is on the 5th index no . but there is no element of the 5th index so it raise an  exception and stops the code \u001b[39;00m\n\u001b[1;32m      6\u001b[0m \u001b[38;5;28mprint\u001b[39m(\u001b[38;5;124m\"\u001b[39m\u001b[38;5;124mCode runs successfully\u001b[39m\u001b[38;5;124m\"\u001b[39m)\n",
      "\u001b[0;31mIndexError\u001b[0m: list index out of range"
     ]
    }
   ],
   "source": [
    "# Q2. What happens when an exception is not handled? Explain with n example\n",
    "#Answer: When the exception is not handled in python code than the code throw an error during the run time and stops the normal flow of \n",
    "        # the program \n",
    "a =  [1,2,3,4,5]    #list of 5 elements\n",
    "a[5]             # we want to access the element that is on the 5th index no . but there is no element of the 5th index so it raise an  exception and stops the code \n",
    "print(\"Code runs successfully\")"
   ]
  },
  {
   "cell_type": "code",
   "execution_count": 22,
   "id": "1bf1854d-4eb9-4635-8f04-fe66f6eab42a",
   "metadata": {},
   "outputs": [
    {
     "name": "stdout",
     "output_type": "stream",
     "text": [
      "division by zero\n",
      "It reaches at print function successfully \n"
     ]
    }
   ],
   "source": [
    "# Q3. Which Python statements are used to catch and handle exceptions? Explain with an example\n",
    "#Answer : try and except statements are used to catch and handle the exception in python \n",
    "#example\n",
    "try:\n",
    "    a = 5\n",
    "    y = a/0\n",
    "    print(y)\n",
    "except Exception as e :\n",
    "        print(e)\n",
    "print(\"It reaches at print function successfully \")\n",
    "#here we handle the exception and because of this print function will execute otherwise it give us an error and the rremaining code will\n",
    "#not executed "
   ]
  },
  {
   "cell_type": "code",
   "execution_count": 27,
   "id": "53784a27-fb75-49a1-bbd1-29ad37da180d",
   "metadata": {},
   "outputs": [
    {
     "name": "stdout",
     "output_type": "stream",
     "text": [
      "10\n",
      "Reached at else block\n"
     ]
    }
   ],
   "source": [
    "# Q4. Explain with an example:\n",
    "# 1 try and else\n",
    "# 2 finally\n",
    "# 3 raise\n",
    "\n",
    "#Answer: \n",
    "      #1.try and else : try block will use to test the code for errors while else block will be execute when there is no error in try block\n",
    "      #2.finally : Finally block alwyas gets executed doesn't matter exception is generated or not\n",
    "      #3.raise : raise is used to raise an exception, we can define what kind of error to raise.\n",
    "# 1. Example\n",
    "try:\n",
    "    a = 5\n",
    "    b = 5\n",
    "    c = a+b\n",
    "    print(c)\n",
    "except Exception as e:\n",
    "    print(e)\n",
    "else:\n",
    "    print(\"Reached at else block\") #else block executed when there is no any exception "
   ]
  },
  {
   "cell_type": "code",
   "execution_count": 28,
   "id": "e6367c65-9f58-420e-9bb5-6d14d0ecc705",
   "metadata": {},
   "outputs": [
    {
     "name": "stdout",
     "output_type": "stream",
     "text": [
      "9\n",
      "Finally will excuted at any condtion \n"
     ]
    }
   ],
   "source": [
    "# 2. Example\n",
    "try:\n",
    "    a = 5\n",
    "    b = 4\n",
    "    print(a+b)\n",
    "except Exception as e:\n",
    "    print(e)\n",
    "finally :\n",
    "    print(\"Finally will excuted at any condtion \")   #finally will excute always"
   ]
  },
  {
   "cell_type": "code",
   "execution_count": 30,
   "id": "1adf4595-9031-47b3-9de0-9e58f8343f83",
   "metadata": {},
   "outputs": [
    {
     "ename": "Exception",
     "evalue": "Sorry, no numbers below zero",
     "output_type": "error",
     "traceback": [
      "\u001b[0;31m---------------------------------------------------------------------------\u001b[0m",
      "\u001b[0;31mException\u001b[0m                                 Traceback (most recent call last)",
      "Cell \u001b[0;32mIn[30], line 4\u001b[0m\n\u001b[1;32m      2\u001b[0m x \u001b[38;5;241m=\u001b[39m \u001b[38;5;241m-\u001b[39m\u001b[38;5;241m1\u001b[39m\n\u001b[1;32m      3\u001b[0m \u001b[38;5;28;01mif\u001b[39;00m x \u001b[38;5;241m<\u001b[39m \u001b[38;5;241m0\u001b[39m :\n\u001b[0;32m----> 4\u001b[0m     \u001b[38;5;28;01mraise\u001b[39;00m \u001b[38;5;167;01mException\u001b[39;00m(\u001b[38;5;124m\"\u001b[39m\u001b[38;5;124mSorry, no numbers below zero\u001b[39m\u001b[38;5;124m\"\u001b[39m)\n",
      "\u001b[0;31mException\u001b[0m: Sorry, no numbers below zero"
     ]
    }
   ],
   "source": [
    "#3. Example\n",
    "x = -1\n",
    "if x < 0 :\n",
    "    raise Exception(\"Sorry, no numbers below zero\")    # we can raise exception at any point of time (depends on developer)"
   ]
  },
  {
   "cell_type": "code",
   "execution_count": 34,
   "id": "016550e5-7f7f-43af-940d-050856cf7892",
   "metadata": {},
   "outputs": [
    {
     "name": "stdout",
     "output_type": "stream",
     "text": [
      "he/she is eligible for vote!!\n",
      "he/she is not eligible for vote!!\n",
      "he/she is not eligible for vote!!\n"
     ]
    }
   ],
   "source": [
    "# Q5. What are Custom Exceptions in python? Why do we need Custom Exceptions? Explain with an example\n",
    "#Answer : Custom exceptions in Python are user-defined exceptions that extend the functionality of the built-in exceptions. Custom \n",
    "        # exceptions in Python are used to create our own exception classes to handle specific error conditions \n",
    "        #In Python there are many  predefined exception but not all, if we want to raise any exception according to our spcefic condition \n",
    "        #then we need custom exceptions\n",
    "#Example\n",
    "def agevalidate(age):\n",
    "    if age >= 18:\n",
    "        print(\"he/she is eligible for vote!!\")\n",
    "    else :\n",
    "        print(\"he/she is not eligible for vote!!\")\n",
    "agevalidate(19)\n",
    "agevalidate(17)\n",
    "agevalidate(-2)  #in this case we need custom exception handling because age can't be negative, we can handle it with if else but the best \n",
    "                # practice is to use custom exception handling\n",
    "    "
   ]
  },
  {
   "cell_type": "code",
   "execution_count": 47,
   "id": "9ca664e1-2ea5-4f72-b518-cb41f9024b4e",
   "metadata": {},
   "outputs": [
    {
     "name": "stdout",
     "output_type": "stream",
     "text": [
      "Insufficient balance\n",
      "\n"
     ]
    }
   ],
   "source": [
    "# Q6. Create custom exception class. Use this class to handle an exception.\n",
    "#Answer \n",
    "class WithdrawalError(Exception):\n",
    "\n",
    "    def __init__(self):\n",
    "        print(\"Insufficient balance\")\n",
    "\n",
    "def Withdrawal(balance, amount):\n",
    "    if amount > balance :\n",
    "        raise WithdrawalError()\n",
    "    else:\n",
    "        balance -= amount\n",
    "        print(\"Withdrawal Successfull!!\",balance)\n",
    "\n",
    "try:\n",
    "    Withdrawal(1000,1500)\n",
    "except Exception as e:\n",
    "    print(e)"
   ]
  },
  {
   "cell_type": "code",
   "execution_count": null,
   "id": "a877b77e-2c70-4c86-98cc-27682e912d70",
   "metadata": {},
   "outputs": [],
   "source": []
  }
 ],
 "metadata": {
  "kernelspec": {
   "display_name": "Python 3 (ipykernel)",
   "language": "python",
   "name": "python3"
  },
  "language_info": {
   "codemirror_mode": {
    "name": "ipython",
    "version": 3
   },
   "file_extension": ".py",
   "mimetype": "text/x-python",
   "name": "python",
   "nbconvert_exporter": "python",
   "pygments_lexer": "ipython3",
   "version": "3.10.8"
  }
 },
 "nbformat": 4,
 "nbformat_minor": 5
}
